Workbook

Sheet Prices
A1: Date | B1: ACWX | C1: AGG | D1: EEM | E1: IEF | F1: RWR | G1: TIP | H1: VNQ | I1: VONV | J1: ^GSPC | K1: ^IRX | L1: ^MID | M1: ^RLG | N1: ^RLV | O1: ^RUT
A2: 42621 | B2: 32.145954 | C2: 84.383873 | D2: 30.513186 | E2: 88.212257 | F2: 70.726501 | G2: 85.3228 | H2: 60.298496 | I2: 37.62851 | J2: 2181.3 | K2: 0.333 | L2: 1574.28 | M2: 1048.34 | N2: 1052.6 | O2: 1258.36
A3: 42622 | B3: 31.440628 | C3: 84.015427 | D3: 29.485104 | E3: 87.793091 | F3: 68.021393 | G3: 84.733727 | H3: 57.910507 | I3: 36.683281 | J3: 2127.8101 | K3: 0.333 | L3: 1528.3101 | M3: 1022.33 | N3: 1026.33 | O3: 1219.21
A4: 42625 | B4: 31.670631 | C4: 84.083084 | D4: 29.685892 | E4: 87.872154 | F4: 68.843468 | G4: 84.763206 | H4: 58.596622 | I4: 37.211967 | J4: 2159.04 | K4: 0.34999999 | L4: 1545.97 | M4: 1037.27 | N4: 1040.87 | O4: 1235.87
A5: 42626 | B5: 31.011305 | C5: 83.850014 | D5: 28.938931 | E5: 87.547874 | F5: 67.079895 | G5: 84.38768 | H5: 57.125469 | I5: 36.583168 | J5: 2127.02 | K5: 0.345 | L5: 1517.26 | M5: 1024.6 | N5: 1022.1 | O5: 1212.3199
A6: 42627 | B6: 31.018967 | C6: 83.955292 | D6: 29.027287 | E6: 87.745552 | F6: 67.353897 | G6: 84.52021 | H6: 57.308372 | I6: 36.430977 | J6: 2125.77 | K6: 0.315 | L6: 1512.78 | M6: 1026.3199 | N6: 1019.09 | O6: 1211.59
A7: 42628 | B7: 31.325634 | C7: 84.007858 | D7: 29.525257 | E7: 87.769333 | F7: 67.606857 | G7: 84.498123 | H7: 57.525108 | I7: 36.823471 | J7: 2147.26 | K7: 0.278 | L7: 1528.6899 | M7: 1037.5 | N7: 1028.47 | O7: 1227.02
A8: 42629 | B8: 30.95763 | C8: 84.068054 | D8: 29.324467 | E8: 87.864243 | F8: 67.591972 | G8: 84.638016 | H8: 57.552204 | I8: 36.607193 | J8: 2139.1599 | K8: 0.273 | L8: 1520.96 | M8: 1034.74 | N8: 1023.56 | O8: 1224.78
A9: 42632 | B9: 31.156969 | C9: 84.000381 | D9: 29.557388 | E9: 87.713959 | F9: 68.179855 | G9: 84.53492 | H9: 58.073719 | I9: 36.675293 | J9: 2139.1201 | K9: 0.23800001 | L9: 1532.39 | M9: 1033.99 | N9: 1025.41 | O9: 1232.53
A10: 42633 | B10: 31.287298 | C10: 84.030426 | D10: 29.573452 | E10: 87.848419 | F10: 68.165672 | G10: 84.52021 | H10: 57.985699 | I10: 36.681328 | J10: 2139.76 | K10: 0.28799999 | L10: 1525.35 | M10: 1035.35 | N10: 1023.89 | O10: 1228.33
A11: 42634 | B11: 31.885292 | C11: 84.24099 | D11: 30.400738 | E11: 87.990746 | F11: 68.994385 | G11: 84.917839 | H11: 58.730751 | I11: 37.05217 | J11: 2163.1201 | K11: 0.223 | L11: 1544.67 | M11: 1045.8101 | N11: 1036.0601 | O11: 1245.04
A12: 42635 | B12: 32.199623 | C12: 84.41394 | D12: 30.617596 | E12: 88.251823 | F12: 70.240982 | G12: 85.337517 | H12: 59.780582 | I12: 37.326271 | J12: 2177.1799 | K12: 0.16 | L12: 1562.9399 | M12: 1053.62 | N12: 1042.71 | O12: 1263.4399
A13: 42636 | B13: 31.877628 | C13: 84.391411 | D13: 30.224035 | E13: 88.291298 | F13: 70.453468 | G13: 85.573143 | H13: 59.963467 | I13: 37.096512 | J13: 2164.6899 | K13: 0.16500001 | L13: 1550.8199 | M13: 1047.95 | N13: 1036.52 | O13: 1254.62
... A47: 42684 | B47: 30.758307 | C47: 82.605705 | D47: 28.288351 | E47: 85.131348 | F47: 62.471031 | G47: 84.358223 | H47: 52.878658 | I47: 37.801918 | J47: 2167.48 | K47: 0.458 | L47: 1547.63 | M47: 1030.1899 | N47: 1053.5 | O47: 1251.61
A48: 42685 | B48: 30.505312 | C48: 82.454773 | D48: 27.750202 | E48: 84.956879 | F48: 62.881851 | G48: 84.122612 | H48: 53.197002 | I48: 37.761604 | J48: 2164.45 | L48: 1562.99 | M48: 1030.37 | N48: 1051.86 | O48: 1282.38
A49: 42688 | B49: 30.305979 | C49: 82.122688 | D49: 27.549416 | E49: 84.465172 | F49: 64.461311 | G49: 83.47467 | H49: 54.456818 | I49: 38.011543 | J49: 2164.2 | K49: 0.50300002 | L49: 1588.12 | M49: 1025.47 | N49: 1059.38 | O49: 1298.6
A50: 42689 | B50: 30.566641 | C50: 82.183044 | D50: 28.103613 | E50: 84.465172 | F50: 63.767189 | G50: 83.526215 | H50: 54.003029 | I50: 38.289661 | J50: 2180.3899 | K50: 0.48800001 | L50: 1595.63 | M50: 1032.78 | N50: 1067.46 | O50: 1302.14
A51: 42690 | B51: 30.28298 | C51: 82.364189 | D51: 27.870689 | E51: 84.544472 | F51: 63.540531 | G51: 83.702866 | H51: 53.84724 | I51: 38.112305 | J51: 2176.9399 | K51: 0.45300001 | L51: 1595.53 | M51: 1035.71 | N51: 1061.41 | O51: 1302.2
A52: 42691 | B52: 30.466976 | C52: 82.054764 | D52: 27.910849 | E52: 84.1717 | F52: 62.903099 | G52: 83.563011 | H52: 53.298595 | I52: 38.229195 | J52: 2187.1201 | K52: 0.41999999 | L52: 1605.24 | M52: 1043.13 | N52: 1064.37 | O52: 1309.48
A53: 42692 | B53: 30.198643 | C53: 81.790619 | D53: 27.782345 | E53: 83.798958 | F53: 63.002258 | G53: 83.437851 | H53: 53.45438 | I53: 38.192909 | J53: 2181.8999 | K53: 0.41800001 | L53: 1605.9301 | M53: 1039.52 | N53: 1063.25 | O53: 1315.64
A54: 42695 | B54: 30.474644 | C54: 81.858482 | D54: 28.055428 | E54: 83.870346 | F54: 62.747284 | G54: 83.63665 | H54: 53.291828 | I54: 38.45895 | J54: 2198.1799 | K54: 0.41999999 | L54: 1616.6801 | M54: 1047.8101 | N54: 1070.59 | O54: 1322.23
A55: 42696 | B55: 30.612648 | C55: 81.934013 | D55: 28.481115 | E55: 83.949623 | F55: 63.788483 | G55: 83.710281 | H55: 54.226543 | I55: 38.555702 | J55: 2202.9399 | K55: 0.47499999 | L55: 1628.53 | M55: 1050.72 | N55: 1072.74 | O55: 1334.34
A56: 42697 | B56: 30.474644 | C56: 81.647202 | D56: 28.175901 | E56: 83.648285 | F56: 63.52639 | G56: 83.43045 | H56: 53.996246 | I56: 38.648418 | J56: 2204.72 | K56: 0.48500001 | L56: 1635.5699 | M56: 1049.98 | N56: 1075.97 | O56: 1342.09
A57: 42699 | B57: 30.589636 | C57: 81.639641 | D57: 28.312443 | E57: 83.576874 | F57: 63.852219 | G57: 83.290573 | H57: 54.307823 | I57: 38.781441 | J57: 2213.3501 | K57: 0.47999999 | L57: 1640.8101 | M57: 1054.01 | N57: 1080.23 | O57: 1347.2
A58: 42702 | B58: 30.489975 | C58: 81.926445 | D58: 28.424889 | E58: 83.957573 | F58: 64.241776 | G58: 83.415764 | H58: 54.55843 | I58: 38.547642 | J58: 2201.72 | K58: 0.44999999 | L58: 1628.6801 | M58: 1049.0601 | N58: 1073.05 | O58: 1329.83
A59: 42703 | B59: 30.620317 | C59: 82.017021 | D59: 28.46505 | E59: 84.0448 | F59: 64.765915 | G59: 83.49678 | H59: 55.079975 | I59: 38.55167 | J59: 2204.6599 | K59: 0.46799999 | L59: 1631.11 | M59: 1052.23 | N59: 1072.62 | O59: 1328.22
A60: 42704 | B60: 30.604973 | C60: 81.692482 | D60: 28.513248 | E60: 83.481712 | F60: 64.185104 | G60: 83.540932 | H60: 54.450066 | I60: 38.757259 | J60: 2198.8101 | K60: 0.46799999 | L60: 1627.52 | M60: 1041.8101 | N60: 1077.79 | O60: 1322.34
... A769: 43734 | B769: 38.18961 | C769: 92.0392 | D769: 35.113865 | E769: 94.427345 | F769: 82.786011 | G769: 91.299606 | H769: 72.390205 | I769: 48.593388 | J769: 2977.6201 | K769: 1.77 | L769: 1936.97 | M769: 1609.27 | N769: 1261.6801 | O769: 1533.33
A770: 43735 | B770: 37.949673 | C770: 92.153259 | D770: 34.661827 | E770: 94.561966 | F770: 82.675354 | G770: 91.158318 | H770: 71.988052 | I770: 48.51543 | J770: 2961.79 | K770: 1.73 | L770: 1922.74 | O770: 1520.48
A771: 43738 | B771: 38.098598 | C771: 92.177666 | D771: 34.857994 | E771: 94.637711 | F771: 82.651649 | G771: 91.236794 | H771: 72.111809 | I771: 48.69733 | J771: 2976.74 | K771: 1.77 | L771: 1935.48 | M771: 1605.39 | N771: 1263.1 | O771: 1523.37
A772: 43739 | B772: 37.77594 | C772: 92.345039 | D772: 34.610649 | E772: 94.899765 | F772: 81.821739 | G772: 91.414436 | H772: 71.431267 | I772: 47.956726 | J772: 2940.25 | K772: 1.753 | L772: 1900.02 | M772: 1589.53 | N772: 1243.9399 | O772: 1493.4301
A773: 43740 | B773: 37.089252 | C773: 92.410301 | D773: 34.346252 | E773: 95.228477 | F773: 81.632034 | G773: 91.414436 | H773: 71.129684 | I773: 47.146839 | J773: 2887.6101 | K773: 1.735 | L773: 1873.8199 | M773: 1561.5601 | N773: 1222.47 | O773: 1479.63
A774: 43741 | B774: 37.387085 | C774: 92.769539 | D774: 34.789764 | E774: 95.725662 | F774: 82.359215 | G774: 91.70517 | H774: 71.81794 | I774: 47.350395 | J774: 2910.6299 | K774: 1.665 | L774: 1884.62 | M774: 1578.83 | N774: 1228.84 | O774: 1486.35
A775: 43742 | B775: 37.684929 | C775: 92.916473 | D775: 34.943287 | E775: 95.911087 | F775: 82.801826 | G775: 91.988068 | H775: 72.251007 | I775: 47.987057 | J775: 2952.01 | K775: 1.655 | L775: 1903.79 | M775: 1602.5699 | N775: 1244.7 | O775: 1500.7
A776: 43745 | B776: 37.536011 | C776: 92.663414 | D776: 34.653301 | E776: 95.590828 | F776: 82.635849 | G776: 91.736641 | H776: 72.096344 | I776: 47.748837 | J776: 2938.79 | K776: 1.673 | L776: 1894.05 | M776: 1596.71 | N776: 1238.74 | O776: 1497.79
A777: 43746 | B777: 37.163715 | C777: 92.696045 | D777: 34.40596 | E777: 95.793083 | F777: 82.248543 | G777: 91.650146 | H777: 71.717392 | I777: 46.951946 | J777: 2893.0601 | K777: 1.655 | L777: 1860.86 | M777: 1571.72 | N777: 1218.5699 | O777: 1472.6
A778: 43747 | B778: 37.461544 | C778: 92.647064 | D778: 34.670361 | E778: 95.548676 | F778: 82.351303 | G778: 91.461563 | H778: 71.85659 | I778: 47.341732 | J778: 2919.3999 | K778: 1.628 | L778: 1873.79 | M778: 1588.9399 | N778: 1227.3199 | O778: 1479.46
A779: 43748 | B779: 37.77594 | C779: 92.328697 | D779: 35.028568 | E779: 94.950363 | F779: 82.422447 | G779: 91.170776 | H779: 71.972595 | I779: 47.705532 | J779: 2938.1299 | K779: 1.633 | L779: 1884.17 | M779: 1597.03 | N779: 1236.04 | O779: 1485.36
A780: 43749 | B780: 38.355064 | C780: 92.026657 | D780: 35.591503 | E780: 94.301491 | F780: 82.46196 | G780: 90.887886 | H780: 71.941681 | I780: 48.194931 | J780: 2970.27 | K780: 1.623 | L780: 1916.5699 | M780: 1615.29 | N780: 1250 | O780: 1511.9
A781: 43752 | B781: 38.239246 | C781: 92.181755 | D781: 35.437958 | E781: 94.562691 | F781: 82.477768 | G781: 91.037163 | H781: 71.972595 | I781: 48.125656 | J781: 2966.1499 | K781: 1.618 | L781: 1909.03 | M781: 1614.38 | N781: 1247.1 | O781: 1505.4301
...

Sheet Returns
A1: Date | B1: ACWX | C1: AGG | D1: EEM | E1: IEF | F1: RWR | G1: TIP | H1: VNQ | I1: VONV | J1: ^GSPC | K1: ^IRX | L1: ^MID | M1: ^RLG | N1: ^RLV | O1: ^RUT
A2: Annual Arithmetic Average | B2: =(1+AVERAGE(B7:B879,B1399:B2484))^252-1 -> 0.08422986 | C2: =(1+AVERAGE(C7:C879,C1399:C2484))^252-1 -> 0.023342289 | D2: =(1+AVERAGE(D7:D879,D1399:D2484))^252-1 -> 0.079635892 | E2: =(1+AVERAGE(E7:E879,E1399:E2484))^252-1 -> 0.014326235 | F2: =(1+AVERAGE(F7:F879,F1399:F2484))^252-1 -> 0.033021617 | G2: =(1+AVERAGE(G7:G879,G1399:G2484))^252-1 -> 0.014786153 | H2: =(1+AVERAGE(H7:H879,H1399:H2484))^252-1 -> 0.031191862 | I2: =(1+AVERAGE(I7:I879,I1399:I2484))^252-1 -> 0.094978166 | ... O2: =(1+AVERAGE(O7:O879,O1399:O2484))^252-1 -> 0.069254547
A3: Standard Deviation | B3: =_xlfn.STDEV.S(B7:B879,B1399:B2484)*SQRT(252) -> 0.14870493 | C3: =_xlfn.STDEV.S(C7:C879,C1399:C2484)*SQRT(252) -> 0.050775353 | D3: =_xlfn.STDEV.S(D7:D879,D1399:D2484)*SQRT(252) -> 0.18623654 | E3: =_xlfn.STDEV.S(E7:E879,E1399:E2484)*SQRT(252) -> 0.066325712 | F3: =_xlfn.STDEV.S(F7:F879,F1399:F2484)*SQRT(252) -> 0.17371515 | G3: =_xlfn.STDEV.S(G7:G879,G1399:G2484)*SQRT(252) -> 0.051998938 | H3: =_xlfn.STDEV.S(H7:H879,H1399:H2484)*SQRT(252) -> 0.17137514 | I3: =_xlfn.STDEV.S(I7:I879,I1399:I2484)*SQRT(252) -> 0.13754132 | ... O3: =_xlfn.STDEV.S(O7:O879,O1399:O2484)*SQRT(252) -> 0.19839628
A4: Skew | B4: =SKEW(B7:B879,B1399:B2484) -> -0.18715326 | C4: =SKEW(C7:C879,C1399:C2484) -> 0.044676854 | D4: =SKEW(D7:D879,D1399:D2484) -> -0.27984006 | E4: =SKEW(E7:E879,E1399:E2484) -> 0.11729158 | F4: =SKEW(F7:F879,F1399:F2484) -> -0.27674381 | G4: =SKEW(G7:G879,G1399:G2484) -> 0.037046192 | H4: =SKEW(H7:H879,H1399:H2484) -> -0.24837675 | I4: =SKEW(I7:I879,I1399:I2484) -> -0.43600693 | ... O4: =SKEW(O7:O879,O1399:O2484) -> -0.070627631
A5: Excess Kurtosis | B5: =KURT(B7:B879,B1399:B2484) -> 4.3177231 | C5: =KURT(C7:C879,C1399:C2484) -> 2.8538865 | D5: =KURT(D7:D879,D1399:D2484) -> 2.6022015 | E5: =KURT(E7:E879,E1399:E2484) -> 1.8853993 | F5: =KURT(F7:F879,F1399:F2484) -> 3.2315239 | G5: =KURT(G7:G879,G1399:G2484) -> 3.5125697 | H5: =KURT(H7:H879,H1399:H2484) -> 3.2319612 | I5: =KURT(I7:I879,I1399:I2484) -> 5.8998982 | ... O5: =KURT(O7:O879,O1399:O2484) -> 2.7052293
A6: 42621
A7: 42622 | B7: =LN(Prices!B3/Prices!B2) -> -0.022185656 | C7: =LN(Prices!C3/Prices!C2) -> -0.0043758726 | D7: =LN(Prices!D3/Prices!D2) -> -0.034273728 | E7: =LN(Prices!E3/Prices!E2) -> -0.0047631207 | F7: =LN(Prices!F3/Prices!F2) -> -0.038998091 | G7: =LN(Prices!G3/Prices!G2) -> -0.0069279968 | H7: =LN(Prices!H3/Prices!H2) -> -0.040408326 | I7: =LN(Prices!I3/Prices!I2) -> -0.025440904 | J7: =LN(Prices!J3/Prices!J2) -> -0.024827742 | K7: =(Prices!K3-Prices!K2)/100 -> 0 | L7: =LN(Prices!L3/Prices!L2) -> -0.029635455 | M7: =LN(Prices!M3/Prices!M2) -> -0.025123576 | N7: =LN(Prices!N3/Prices!N2) -> -0.025273981 | O7: =LN(Prices!O3/Prices!O2) -> -0.031606198
A8: 42625 | B8: =LN(Prices!B4/Prices!B3) -> 0.0072888539 | C8: =LN(Prices!C4/Prices!C3) -> 0.00080497411 | D8: =LN(Prices!D4/Prices!D3) -> 0.0067867463 | E8: =LN(Prices!E4/Prices!E3) -> 0.00090016008 | F8: =LN(Prices!F4/Prices!F3) -> 0.012013088 | G8: =LN(Prices!G4/Prices!G3) -> 0.00034785267 | H8: =LN(Prices!H4/Prices!H3) -> 0.011778218 | I8: =LN(Prices!I4/Prices!I3) -> 0.014309325 | J8: =LN(Prices!J4/Prices!J3) -> 0.014570387 | K8: =(Prices!K4-Prices!K3)/100 -> 0.0001699999 | L8: =LN(Prices!L4/Prices!L3) -> 0.011488938 | M8: =LN(Prices!M4/Prices!M3) -> 0.014507928 | N8: =LN(Prices!N4/Prices!N3) -> 0.014067608 | O8: =LN(Prices!O4/Prices!O3) -> 0.013572096
A9: 42626 | B9: =LN(Prices!B5/Prices!B4) -> -0.021037987 | C9: =LN(Prices!C5/Prices!C4) -> -0.0027757545 | D9: =LN(Prices!D5/Prices!D4) -> -0.025484155 | E9: =LN(Prices!E5/Prices!E4) -> -0.0036971851 | F9: =LN(Prices!F5/Prices!F4) -> -0.025950972 | G9: =LN(Prices!G5/Prices!G4) -> -0.0044401428 | H9: =LN(Prices!H5/Prices!H4) -> -0.025426995 | I9: =LN(Prices!I5/Prices!I4) -> -0.017042171 | J9: =LN(Prices!J5/Prices!J4) -> -0.014941748 | K9: =(Prices!K5-Prices!K4)/100 -> -4.9999952e-05 | L9: =LN(Prices!L5/Prices!L4) -> -0.018745443 | M9: =LN(Prices!M5/Prices!M4) -> -0.012290012 | N9: =LN(Prices!N5/Prices!N4) -> -0.018197587 | O9: =LN(Prices!O5/Prices!O4) -> -0.019239337
A10: 42627 | B10: =LN(Prices!B6/Prices!B5) -> 0.00024703485 | C10: =LN(Prices!C6/Prices!C5) -> 0.001254764 | D10: =LN(Prices!D6/Prices!D5) -> 0.0030485373 | E10: =LN(Prices!E6/Prices!E5) -> 0.002255392 | F10: =LN(Prices!F6/Prices!F5) -> 0.0040763926 | G10: =LN(Prices!G6/Prices!G5) -> 0.0015692605 | H10: =LN(Prices!H6/Prices!H5) -> 0.003196667 | I10: =LN(Prices!I6/Prices!I5) -> -0.0041688191 | J10: =LN(Prices!J6/Prices!J5) -> -0.0005878494 | K10: =(Prices!K6-Prices!K5)/100 -> -0.00030000001 | L10: =LN(Prices!L6/Prices!L5) -> -0.0029570459 | M10: =LN(Prices!M6/Prices!M5) -> 0.0016772679 | N10: =LN(Prices!N6/Prices!N5) -> -0.0029492119 | O10: =LN(Prices!O6/Prices!O5) -> -0.00060231652
A11: 42628 | B11: =LN(Prices!B7/Prices!B6) -> 0.0098378945 | C11: =LN(Prices!C7/Prices!C6) -> 0.00062592932 | D11: =LN(Prices!D7/Prices!D6) -> 0.017009768 | E11: =LN(Prices!E7/Prices!E6) -> 0.00027098355 | F11: =LN(Prices!F7/Prices!F6) -> 0.0037486527 | G11: =LN(Prices!G7/Prices!G6) -> -0.00026135741 | H11: =LN(Prices!H7/Prices!H6) -> 0.0037747893 | I11: =LN(Prices!I7/Prices!I6) -> 0.010716017 | J11: =LN(Prices!J7/Prices!J6) -> 0.010058516 | K11: =(Prices!K7-Prices!K6)/100 -> -0.00037 | L11: =LN(Prices!L7/Prices!L6) -> 0.010462084 | M11: =LN(Prices!M7/Prices!M6) -> 0.010834436 | N11: =LN(Prices!N7/Prices!N6) -> 0.0091621339 | O11: =LN(Prices!O7/Prices!O6) -> 0.012654963
A12: 42629 | B12: =LN(Prices!B8/Prices!B7) -> -0.01181724 | C12: =LN(Prices!C8/Prices!C7) -> 0.0007162945 | D12: =LN(Prices!D8/Prices!D7) -> -0.0068238616 | E12: =LN(Prices!E8/Prices!E7) -> 0.0010807692 | F12: =LN(Prices!F8/Prices!F7) -> -0.00022019346 | G12: =LN(Prices!G8/Prices!G7) -> 0.0016542013 | H12: =LN(Prices!H8/Prices!H7) -> 0.00047091463 | I12: =LN(Prices!I8/Prices!I7) -> -0.0058906917 | J12: =LN(Prices!J8/Prices!J7) -> -0.0037794278 | K12: =(Prices!K8-Prices!K7)/100 -> -4.9999952e-05 | L12: =LN(Prices!L8/Prices!L7) -> -0.0050694324 | M12: =LN(Prices!M8/Prices!M7) -> -0.0026637951 | N12: =LN(Prices!N8/Prices!N7) -> -0.0047854881 | O12: =LN(Prices!O8/Prices!O7) -> -0.0018272215
A13: 42632 | B13: =LN(Prices!B9/Prices!B8) -> 0.0064184459 | C13: =LN(Prices!C9/Prices!C8) -> -0.00080529973 | D13: =LN(Prices!D9/Prices!D8) -> 0.0079115312 | E13: =LN(Prices!E9/Prices!E8) -> -0.0017118737 | F13: =LN(Prices!F9/Prices!F8) -> 0.0086599213 | G13: =LN(Prices!G9/Prices!G8) -> -0.001218824 | H13: =LN(Prices!H9/Prices!H8) -> 0.0090207873 | I13: =LN(Prices!I9/Prices!I8) -> 0.0018585613 | J13: =LN(Prices!J9/Prices!J8) -> -1.8603234e-05 | K13: =(Prices!K9-Prices!K8)/100 -> -0.00034999996 | L13: =LN(Prices!L9/Prices!L8) -> 0.0074869289 | M13: =LN(Prices!M9/Prices!M8) -> -0.00072508258 | N13: =LN(Prices!N9/Prices!N8) -> 0.0018058216 | O13: =LN(Prices!O9/Prices!O8) -> 0.0063077312
A14: 42633 | B14: =LN(Prices!B10/Prices!B9) -> 0.0041742606 | C14: =LN(Prices!C10/Prices!C9) -> 0.00035760771 | D14: =LN(Prices!D10/Prices!D9) -> 0.00054332698 | E14: =LN(Prices!E10/Prices!E9) -> 0.0015317687 | F14: =LN(Prices!F10/Prices!F9) -> -0.00020804561 | G14: =LN(Prices!G10/Prices!G9) -> -0.00017401983 | H14: =LN(Prices!H10/Prices!H9) -> -0.0015168152 | I14: =LN(Prices!I10/Prices!I9) -> 0.0001645346 | J14: =LN(Prices!J10/Prices!J9) -> 0.00029909348 | K14: =(Prices!K10-Prices!K9)/100 -> 0.00049999982 | L14: =LN(Prices!L10/Prices!L9) -> -0.0046047418 | M14: =LN(Prices!M10/Prices!M9) -> 0.0013144148 | N14: =LN(Prices!N10/Prices!N9) -> -0.0014834527 | O14: =LN(Prices!O10/Prices!O9) -> -0.0034135037
A15: 42634 | B15: =LN(Prices!B11/Prices!B10) -> 0.018932632 | C15: =LN(Prices!C11/Prices!C10) -> 0.0025026683 | D15: =LN(Prices!D11/Prices!D10) -> 0.02758981 | E15: =LN(Prices!E11/Prices!E10) -> 0.0016188246 | F15: =LN(Prices!F11/Prices!F10) -> 0.012084022 | G15: =LN(Prices!G11/Prices!G10) -> 0.0046935091 | H15: =LN(Prices!H11/Prices!H10) -> 0.012767051 | I15: =LN(Prices!I11/Prices!I10) -> 0.010059067 | J15: =LN(Prices!J11/Prices!J10) -> 0.010858 | K15: =(Prices!K11-Prices!K10)/100 -> -0.00064999983 | L15: =LN(Prices!L11/Prices!L10) -> 0.012586448 | M15: =LN(Prices!M11/Prices!M10) -> 0.010052251 | N15: =LN(Prices!N11/Prices!N10) -> 0.011816 | O15: =LN(Prices!O11/Prices!O10) -> 0.013512202
A16: 42635 | B16: =LN(Prices!B12/Prices!B11) -> 0.0098099085 | C16: =LN(Prices!C12/Prices!C11) -> 0.0020509428 | D16: =LN(Prices!D12/Prices!D11) -> 0.0071079891 | E16: =LN(Prices!E12/Prices!E11) -> 0.002962713 | F16: =LN(Prices!F12/Prices!F11) -> 0.01790681 | G16: =LN(Prices!G12/Prices!G11) -> 0.0049299898 | H16: =LN(Prices!H12/Prices!H11) -> 0.017717442 | I16: =LN(Prices!I12/Prices!I11) -> 0.0073704825 | J16: =LN(Prices!J12/Prices!J11) -> 0.0064787519 | K16: =(Prices!K12-Prices!K11)/100 -> -0.00063000008 | L16: =LN(Prices!L12/Prices!L11) -> 0.011758302 | M16: =LN(Prices!M12/Prices!M11) -> 0.0074400884 | N16: =LN(Prices!N12/Prices!N11) -> 0.006397942 | O16: =LN(Prices!O12/Prices!O11) -> 0.014670424
A17: 42636 | B17: =LN(Prices!B13/Prices!B12) -> -0.01005029 | C17: =LN(Prices!C13/Prices!C12) -> -0.00026692995 | D17: =LN(Prices!D13/Prices!D12) -> -0.012937388 | E17: =LN(Prices!E13/Prices!E12) -> 0.00044719372 | F17: =LN(Prices!F13/Prices!F12) -> 0.0030205375 | G17: =LN(Prices!G13/Prices!G12) -> 0.0027573046 | H17: =LN(Prices!H13/Prices!H12) -> 0.0030545878 | I17: =LN(Prices!I13/Prices!I12) -> -0.0061744519 | J17: =LN(Prices!J13/Prices!J12) -> -0.005753293 | K17: =(Prices!K13-Prices!K12)/100 -> 5.0000101e-05 | L17: =LN(Prices!L13/Prices!L12) -> -0.0077848368 | M17: =LN(Prices!M13/Prices!M12) -> -0.0053960209 | N17: =LN(Prices!N13/Prices!N12) -> -0.0059540885 | O17: =LN(Prices!O13/Prices!O12) -> -0.0070053792
A18: 42639 | B18: =LN(Prices!B14/Prices!B13) -> -0.011124858 | C18: =LN(Prices!C14/Prices!C13) -> 0.0012460873 | D18: =LN(Prices!D14/Prices!D13) -> -0.014723765 | E18: =LN(Prices!E14/Prices!E13) -> 0.0028630353 | F18: =LN(Prices!F14/Prices!F13) -> 0.0023093195 | G18: =LN(Prices!G14/Prices!G13) -> 0.00042973072 | H18: =LN(Prices!H14/Prices!H13) -> 0.0023692155 | I18: =LN(Prices!I14/Prices!I13) -> -0.0088403257 | J18: =LN(Prices!J14/Prices!J13) -> -0.0086248501 | K18: =(Prices!K14-Prices!K13)/100 -> 7.9999864e-05 | L18: =LN(Prices!L14/Prices!L13) -> -0.0053663333 | M18: =LN(Prices!M14/Prices!M13) -> -0.0076823734 | N18: =LN(Prices!N14/Prices!N13) -> -0.0087695259 | O18: =LN(Prices!O14/Prices!O13) -> -0.010963624
... A773: 43734 | B773: =LN(Prices!B769/Prices!B768) -> 0.0026033798 | C773: =LN(Prices!C769/Prices!C768) -> 0.0016825653 | D773: =LN(Prices!D769/Prices!D768) -> -0.00024277628 | E773: =LN(Prices!E769/Prices!E768) -> 0.0021408914 | F773: =LN(Prices!F769/Prices!F768) -> 0.0094970493 | G773: =LN(Prices!G769/Prices!G768) -> 0.00060234626 | H773: =LN(Prices!H769/Prices!H768) -> 0.0083675686 | I773: =LN(Prices!I769/Prices!I768) -> -0.0032656996 | J773: =LN(Prices!J769/Prices!J768) -> -0.002431871 | K773: =(Prices!K769-Prices!K768)/100 -> -0.00075000048 | L773: =LN(Prices!L769/Prices!L768) -> -0.0053857009 | M773: =LN(Prices!M769/Prices!M768) -> -0.0019368872 | N773: =LN(Prices!N769/Prices!N768) -> -0.0034418345 | O773: =LN(Prices!O769/Prices!O768) -> -0.011232401
A774: 43735 | B774: =LN(Prices!B770/Prices!B769) -> -0.0063025974 | C774: =LN(Prices!C770/Prices!C769) -> 0.0012384814 | D774: =LN(Prices!D770/Prices!D769) -> -0.012957066 | E774: =LN(Prices!E770/Prices!E769) -> 0.0014246381 | F774: =LN(Prices!F770/Prices!F769) -> -0.001337554 | G774: =LN(Prices!G770/Prices!G769) -> -0.0015487273 | H774: =LN(Prices!H770/Prices!H769) -> -0.0055708396 | I774: =LN(Prices!I770/Prices!I769) -> -0.0016055632 | J774: =LN(Prices!J770/Prices!J769) -> -0.0053305346 | K774: =(Prices!K770-Prices!K769)/100 -> -0.00039999962 | L774: =LN(Prices!L770/Prices!L769) -> -0.0073736343 | O774: =LN(Prices!O770/Prices!O769) -> -0.0084157506
A775: 43738 | B775: =LN(Prices!B771/Prices!B770) -> 0.0039166169 | C775: =LN(Prices!C771/Prices!C770) -> 0.00026481105 | D775: =LN(Prices!D771/Prices!D770) -> 0.0056434988 | E775: =LN(Prices!E771/Prices!E770) -> 0.00080068459 | F775: =LN(Prices!F771/Prices!F770) -> -0.00028675931 | G775: =LN(Prices!G771/Prices!G770) -> 0.00086050505 | H775: =LN(Prices!H771/Prices!H770) -> 0.0017176483 | I775: =LN(Prices!I771/Prices!I770) -> 0.0037423119 | J775: =LN(Prices!J771/Prices!J770) -> 0.0050349102 | K775: =(Prices!K771-Prices!K770)/100 -> 0.00039999962 | L775: =LN(Prices!L771/Prices!L770) -> 0.0066041007 | O775: =LN(Prices!O771/Prices!O770) -> 0.0018989211
A776: 43739 | B776: =LN(Prices!B772/Prices!B771) -> -0.0085051057 | C776: =LN(Prices!C772/Prices!C771) -> 0.0018141258 | D776: =LN(Prices!D772/Prices!D771) -> -0.0071210838 | E776: =LN(Prices!E772/Prices!E771) -> 0.002765201 | F776: =LN(Prices!F772/Prices!F771) -> -0.010091813 | G776: =LN(Prices!G772/Prices!G771) -> 0.0019451594 | H776: =LN(Prices!H772/Prices!H771) -> -0.0094821306 | I776: =LN(Prices!I772/Prices!I771) -> -0.015325149 | J776: =LN(Prices!J772/Prices!J771) -> -0.012334127 | K776: =(Prices!K772-Prices!K771)/100 -> -0.0001699996 | L776: =LN(Prices!L772/Prices!L771) -> -0.018490925 | M776: =LN(Prices!M772/Prices!M771) -> -0.0099283334 | N776: =LN(Prices!N772/Prices!N771) -> -0.015285283 | O776: =LN(Prices!O772/Prices!O771) -> -0.019849459
A777: 43740 | B777: =LN(Prices!B773/Prices!B772) -> -0.018345154 | C777: =LN(Prices!C773/Prices!C772) -> 0.00070646774 | D777: =LN(Prices!D773/Prices!D772) -> -0.0076684989 | E777: =LN(Prices!E773/Prices!E772) -> 0.0034578008 | F777: =LN(Prices!F773/Prices!F772) -> -0.0023212065 | G777: =LN(Prices!G773/Prices!G772) -> 0 | H777: =LN(Prices!H773/Prices!H772) -> -0.0042309312 | I777: =LN(Prices!I773/Prices!I772) -> -0.017032096 | J777: =LN(Prices!J773/Prices!J772) -> -0.018065404 | K777: =(Prices!K773-Prices!K772)/100 -> -0.00018000007 | L777: =LN(Prices!L773/Prices!L772) -> -0.013885323 | M777: =LN(Prices!M773/Prices!M772) -> -0.017753034 | N777: =LN(Prices!N773/Prices!N772) -> -0.017410336 | O777: =LN(Prices!O773/Prices!O772) -> -0.009283464
A778: 43741 | B778: =LN(Prices!B774/Prices!B773) -> 0.007998086 | C778: =LN(Prices!C774/Prices!C773) -> 0.0038798837 | D778: =LN(Prices!D774/Prices!D773) -> 0.012830304 | E778: =LN(Prices!E774/Prices!E773) -> 0.0052073852 | F778: =LN(Prices!F774/Prices!F773) -> 0.008868586 | G778: =LN(Prices!G774/Prices!G773) -> 0.0031753408 | H778: =LN(Prices!H774/Prices!H773) -> 0.0096295497 | I778: =LN(Prices!I774/Prices!I773) -> 0.0043081975 | J778: =LN(Prices!J774/Prices!J773) -> 0.0079403048 | K778: =(Prices!K774-Prices!K773)/100 -> -0.00070000052 | L778: =LN(Prices!L774/Prices!L773) -> 0.0057471072 | M778: =LN(Prices!M774/Prices!M773) -> 0.010998679 | N778: =LN(Prices!N774/Prices!N773) -> 0.0051972289 | O778: =LN(Prices!O774/Prices!O773) -> 0.0045313739
A779: 43742 | B779: =LN(Prices!B775/Prices!B774) -> 0.0079349276 | C779: =LN(Prices!C775/Prices!C774) -> 0.0015826129 | D779: =LN(Prices!D775/Prices!D774) -> 0.0044031557 | E779: =LN(Prices!E775/Prices!E774) -> 0.0019351702 | F779: =LN(Prices!F775/Prices!F774) -> 0.0053597719 | G779: =LN(Prices!G775/Prices!G774) -> 0.0030801153 | H779: =LN(Prices!H775/Prices!H774) -> 0.0060119635 | I779: =LN(Prices!I775/Prices!I774) -> 0.013356157 | J779: =LN(Prices!J775/Prices!J774) -> 0.014116785 | K779: =(Prices!K775-Prices!K774)/100 -> -9.9999905e-05 | L779: =LN(Prices!L775/Prices!L774) -> 0.01012045 | M779: =LN(Prices!M775/Prices!M774) -> 0.014924519 | N779: =LN(Prices!N775/Prices!N774) -> 0.012823891 | O779: =LN(Prices!O775/Prices!O774) -> 0.0096081996
A780: 43745 | B780: =LN(Prices!B776/Prices!B775) -> -0.0039594918 | C780: =LN(Prices!C776/Prices!C775) -> -0.0027272303 | D780: =LN(Prices!D776/Prices!D775) -> -0.0083333779 | E780: =LN(Prices!E776/Prices!E775) -> -0.0033447122 | F780: =LN(Prices!F776/Prices!F775) -> -0.0020065264 | G780: =LN(Prices!G776/Prices!G775) -> -0.0027369955 | H780: =LN(Prices!H776/Prices!H775) -> -0.0021429301 | I780: =LN(Prices!I776/Prices!I775) -> -0.0049766226 | J780: =LN(Prices!J776/Prices!J775) -> -0.0044883523 | K780: =(Prices!K776-Prices!K775)/100 -> 0.00018000007 | L780: =LN(Prices!L776/Prices!L775) -> -0.0051292373 | M780: =LN(Prices!M776/Prices!M775) -> -0.0036633193 | N780: =LN(Prices!N776/Prices!N775) -> -0.0047997717 | O780: =LN(Prices!O776/Prices!O775) -> -0.001940919
A781: 43746 | B781: =LN(Prices!B777/Prices!B776) -> -0.0099678669 | C781: =LN(Prices!C777/Prices!C776) -> 0.00035208261 | D781: =LN(Prices!D777/Prices!D776) -> -0.0071631874 | E781: =LN(Prices!E777/Prices!E776) -> 0.0021136084 | F781: =LN(Prices!F777/Prices!F776) -> -0.004697921 | G781: =LN(Prices!G777/Prices!G776) -> -0.00094330081 | H781: =LN(Prices!H777/Prices!H776) -> -0.0052700516 | I781: =LN(Prices!I777/Prices!I776) -> -0.016830042 | J781: =LN(Prices!J777/Prices!J776) -> -0.01568316 | K781: =(Prices!K777-Prices!K776)/100 -> -0.00018000007 | L781: =LN(Prices!L777/Prices!L776) -> -0.017678681 | M781: =LN(Prices!M777/Prices!M776) -> -0.015774695 | N781: =LN(Prices!N777/Prices!N776) -> -0.01641673 | O781: =LN(Prices!O777/Prices!O776) -> -0.016961185
A782: 43747 | B782: =LN(Prices!B778/Prices!B777) -> 0.0079820227 | C782: =LN(Prices!C778/Prices!C777) -> -0.00052854098 | D782: =LN(Prices!D778/Prices!D777) -> 0.007655352 | E782: =LN(Prices!E778/Prices!E777) -> -0.0025546727 | F782: =LN(Prices!F778/Prices!F777) -> 0.0012486078 | G782: =LN(Prices!G778/Prices!G777) -> -0.0020597639 | H782: =LN(Prices!H778/Prices!H777) -> 0.001939047 | I782: =LN(Prices!I778/Prices!I777) -> 0.0082675317 | J782: =LN(Prices!J778/Prices!J777) -> 0.0090632965 | K782: =(Prices!K778-Prices!K777)/100 -> -0.0002699995 | L782: =LN(Prices!L778/Prices!L777) -> 0.0069244 | M782: =LN(Prices!M778/Prices!M777) -> 0.010896548 | N782: =LN(Prices!N778/Prices!N777) -> 0.0071548906 | O782: =LN(Prices!O778/Prices!O777) -> 0.0046476006
A783: 43748 | B783: =LN(Prices!B779/Prices!B778) -> 0.008357476 | C783: =LN(Prices!C779/Prices!C778) -> -0.0034422599 | D783: =LN(Prices!D779/Prices!D778) -> 0.010278805 | E783: =LN(Prices!E779/Prices!E778) -> -0.0062815471 | F783: =LN(Prices!F779/Prices!F778) -> 0.00086353692 | G783: =LN(Prices!G779/Prices!G778) -> -0.0031843976 | H783: =LN(Prices!H779/Prices!H778) -> 0.0016130936 | I783: =LN(Prices!I779/Prices!I778) -> 0.0076551772 | J783: =LN(Prices!J779/Prices!J778) -> 0.0063952024 | K783: =(Prices!K779-Prices!K778)/100 -> 4.9999952e-05 | L783: =LN(Prices!L779/Prices!L778) -> 0.0055242903 | M783: =LN(Prices!M779/Prices!M778) -> 0.0050785823 | N783: =LN(Prices!N779/Prices!N778) -> 0.0070798659 | O783: =LN(Prices!O779/Prices!O778) -> 0.0039800273
A784: 43749 | B784: =LN(Prices!B780/Prices!B779) -> 0.015214186 | C784: =LN(Prices!C780/Prices!C779) -> -0.0032767193 | D784: =LN(Prices!D780/Prices!D779) -> 0.015942969 | E784: =LN(Prices!E780/Prices!E779) -> -0.0068572635 | F784: =LN(Prices!F780/Prices!F779) -> 0.00047927679 | G784: =LN(Prices!G780/Prices!G779) -> -0.0031076857 | H784: =LN(Prices!H780/Prices!H779) -> -0.00042962113 | I784: =LN(Prices!I780/Prices!I779) -> 0.010206483 | J784: =LN(Prices!J780/Prices!J779) -> 0.01087958 | K784: =(Prices!K780-Prices!K779)/100 -> -9.9999905e-05 | L784: =LN(Prices!L780/Prices!L779) -> 0.017049673 | M784: =LN(Prices!M780/Prices!M779) -> 0.011368859 | N784: =LN(Prices!N780/Prices!N779) -> 0.011230799 | O784: =LN(Prices!O780/Prices!O779) -> 0.017709997
A785: 43752 | B785: =LN(Prices!B781/Prices!B780) -> -0.0030241962 | C785: =LN(Prices!C781/Prices!C780) -> 0.0016839404 | D785: =LN(Prices!D781/Prices!D780) -> -0.0043234347 | E785: =LN(Prices!E781/Prices!E780) -> 0.0027660101 | F785: =LN(Prices!F781/Prices!F780) -> 0.00019168342 | G785: =LN(Prices!G781/Prices!G780) -> 0.0016410799 | H785: =LN(Prices!H781/Prices!H780) -> 0.00042962113 | I785: =LN(Prices!I781/Prices!I780) -> -0.0014384238 | J785: =LN(Prices!J781/Prices!J780) -> -0.0013880817 | K785: =(Prices!K781-Prices!K780)/100 -> -4.9999952e-05 | L785: =LN(Prices!L781/Prices!L780) -> -0.0039418271 | M785: =LN(Prices!M781/Prices!M780) -> -0.00056354624 | N785: =LN(Prices!N781/Prices!N780) -> -0.0023227149 | O785: =LN(Prices!O781/Prices!O780) -> -0.0042885468
A786: 43753 | B786: =LN(Prices!B782/Prices!B781) -> 0.010117251 | C786: =LN(Prices!C782/Prices!C781) -> -0.0032821172 | D786: =LN(Prices!D782/Prices!D781) -> 0.0088657874 | E786: =LN(Prices!E782/Prices!E781) -> -0.0048237418 | F786: =LN(Prices!F782/Prices!F781) -> 0.0030616716 | G786: =LN(Prices!G782/Prices!G781) -> -0.0033724735 | H786: =LN(Prices!H782/Prices!H781) -> 0.0012883923 | I786: =LN(Prices!I782/Prices!I781) -> 0.0072626466 | J786: =LN(Prices!J782/Prices!J781) -> 0.0099064454 | K786: =(Prices!K782-Prices!K781)/100 -> 0 | L786: =LN(Prices!L782/Prices!L781) -> 0.0079722174 | M786: =LN(Prices!M782/Prices!M781) -> 0.010990048 | N786: =LN(Prices!N782/Prices!N781) -> 0.0083207066 | O786: =LN(Prices!O782/Prices!O781) -> 0.011800459
A787: 43754 | B787: =LN(Prices!B783/Prices!B782) -> 0.0012842673 | C787: =LN(Prices!C783/Prices!C782) -> 0.0017755759 | D787: =LN(Prices!D783/Prices!D782) -> 0.0028585174 | E787: =LN(Prices!E783/Prices!E782) -> 0.0019681667 | F787: =LN(Prices!F783/Prices!F782) -> 0.00076411673 | G787: =LN(Prices!G783/Prices!G782) -> 0.0015581205 | H787: =LN(Prices!H783/Prices!H782) -> 0.00010734406 | I787: =LN(Prices!I783/Prices!I782) -> -0.00062555908 | J787: =LN(Prices!J783/Prices!J782) -> -0.0020015446 | K787: =(Prices!K783-Prices!K782)/100 -> -3.000021e-05 | L787: =LN(Prices!L783/Prices!L782) -> -0.00099307424 | M787: =LN(Prices!M783/Prices!M782) -> -0.0037442273 | N787: =LN(Prices!N783/Prices!N782) -> -0.0013209578 | O787: =LN(Prices!O783/Prices!O782) -> 0.0011547258
... A879: 43889 | B879: =LN(Prices!B875/Prices!B874) -> -0.0060791193 | C879: =LN(Prices!C875/Prices!C874) -> 0.0073404913 | D879: =LN(Prices!D875/Prices!D874) -> -0.0036951754 | E879: =LN(Prices!E875/Prices!E874) -> 0.01114826 | F879: =LN(Prices!F875/Prices!F874) -> -0.023674115 | G879: =LN(Prices!G875/Prices!G874) -> 0.0015838973 | H879: =LN(Prices!H875/Prices!H874) -> -0.024432692 | I879: =LN(Prices!I875/Prices!I874) -> -0.014709707 | J879: =LN(Prices!J875/Prices!J874) -> -0.0082724631 | K879: =(Prices!K875-Prices!K874)/100 -> -0.0016499996 | L879: =LN(Prices!L875/Prices!L874) -> -0.020629219 | M879: =LN(Prices!M875/Prices!M874) -> -0.0017803736 | N879: =LN(Prices!N875/Prices!N874) -> -0.016118301 | O879: =LN(Prices!O875/Prices!O874) -> -0.014417048
A881: 43892 | B881: =LN(Prices!B876/Prices!B875) -> 0.015907296 | C881: =LN(Prices!C876/Prices!C875) -> -0.00035338105 | D881: =LN(Prices!D876/Prices!D875) -> 0.021485273 | E881: =LN(Prices!E876/Prices!E875) -> -0.00068293411 | F881: =LN(Prices!F876/Prices!F875) -> 0.036485485 | G881: =LN(Prices!G876/Prices!G875) -> 0.0023301263 | H881: =LN(Prices!H876/Prices!H875) -> 0.041824531 | I881: =LN(Prices!I876/Prices!I875) -> 0.039238746 | J881: =LN(Prices!J876/Prices!J875) -> 0.045010869 | K881: =(Prices!K876-Prices!K875)/100 -> -0.00095000029 | L881: =LN(Prices!L876/Prices!L875) -> 0.033324927 | M881: =LN(Prices!M876/Prices!M875) -> 0.046191899 | N881: =LN(Prices!N876/Prices!N875) -> 0.040681662 | O881: =LN(Prices!O876/Prices!O875) -> 0.028089366
A882: 43893 | B882: =LN(Prices!B877/Prices!B876) -> -0.0064667434 | C882: =LN(Prices!C877/Prices!C876) -> 0.006790612 | D882: =LN(Prices!D877/Prices!D876) -> -0.0067861177 | E882: =LN(Prices!E877/Prices!E876) -> 0.011552997 | F882: =LN(Prices!F877/Prices!F876) -> -0.0041147653 | G882: =LN(Prices!G877/Prices!G876) -> 0.010089254 | H882: =LN(Prices!H877/Prices!H876) -> -0.0023085076 | I882: =LN(Prices!I877/Prices!I876) -> -0.023692348 | J882: =LN(Prices!J877/Prices!J876) -> -0.028510485 | K882: =(Prices!K877-Prices!K876)/100 -> -0.0021700001 | L882: =LN(Prices!L877/Prices!L876) -> -0.021711293 | M882: =LN(Prices!M877/Prices!M876) -> -0.029755554 | N882: =LN(Prices!N877/Prices!N876) -> -0.025459851 | O882: =LN(Prices!O877/Prices!O876) -> -0.021574663
A883: 43894 | B883: =LN(Prices!B878/Prices!B877) -> 0.023436799 | C883: =LN(Prices!C878/Prices!C877) -> -0.00077134287 | D883: =LN(Prices!D878/Prices!D877) -> 0.017597008 | E883: =LN(Prices!E878/Prices!E877) -> -0.0021984773 | F883: =LN(Prices!F878/Prices!F877) -> 0.036139209 | G883: =LN(Prices!G878/Prices!G877) -> -0.0014818628 | H883: =LN(Prices!H878/Prices!H877) -> 0.037059156 | I883: =LN(Prices!I878/Prices!I877) -> 0.037482066 | J883: =LN(Prices!J878/Prices!J877) -> 0.041336349 | K883: =(Prices!K878-Prices!K877)/100 -> -0.0024299997 | L883: =LN(Prices!L878/Prices!L877) -> 0.034526954 | M883: =LN(Prices!M878/Prices!M877) -> 0.041735932 | N883: =LN(Prices!N878/Prices!N877) -> 0.038777889 | O883: =LN(Prices!O878/Prices!O877) -> 0.029909959
A884: 43895 | B884: =LN(Prices!B879/Prices!B878) -> -0.024108263 | C884: =LN(Prices!C879/Prices!C878) -> 0.0030815709 | D884: =LN(Prices!D879/Prices!D878) -> -0.021251563 | E884: =LN(Prices!E879/Prices!E878) -> 0.0088487184 | F884: =LN(Prices!F879/Prices!F878) -> -0.023438071 | G884: =LN(Prices!G879/Prices!G878) -> 0.0031264416 | H884: =LN(Prices!H879/Prices!H878) -> -0.021658538 | I884: =LN(Prices!I879/Prices!I878) -> -0.033309076 | J884: =LN(Prices!J879/Prices!J878) -> -0.034510782 | K884: =(Prices!K879-Prices!K878)/100 -> -0.00079999983 | L884: =LN(Prices!L879/Prices!L878) -> -0.037020236 | M884: =LN(Prices!M879/Prices!M878) -> -0.033281824 | N884: =LN(Prices!N879/Prices!N878) -> -0.035560769 | O884: =LN(Prices!O879/Prices!O878) -> -0.034807274
A885: 43896 | B885: =LN(Prices!B880/Prices!B879) -> -0.014658023 | C885: =LN(Prices!C880/Prices!C879) -> 0.0073241513 | D885: =LN(Prices!D880/Prices!D879) -> -0.020716232 | E885: =LN(Prices!E880/Prices!E879) -> 0.010100491 | F885: =LN(Prices!F880/Prices!F879) -> -0.018283279 | G885: =LN(Prices!G880/Prices!G879) -> 0.006631728 | H885: =LN(Prices!H880/Prices!H879) -> -0.017383912 | I885: =LN(Prices!I880/Prices!I879) -> -0.020474635 | J885: =LN(Prices!J880/Prices!J879) -> -0.017200944 | K885: =(Prices!K880-Prices!K879)/100 -> -0.0018000004 | L885: =LN(Prices!L880/Prices!L879) -> -0.01809655 | M885: =LN(Prices!M880/Prices!M879) -> -0.015808197 | N885: =LN(Prices!N880/Prices!N879) -> -0.020017007 | O885: =LN(Prices!O880/Prices!O879) -> -0.020218976
A886: 43899 | B886: =LN(Prices!B881/Prices!B880) -> -0.083342095 | C886: =LN(Prices!C881/Prices!C880) -> -0.0012737483 | D886: =LN(Prices!D881/Prices!D880) -> -0.070720696 | E886: =LN(Prices!E881/Prices!E880) -> 0.0089299819 | F886: =LN(Prices!F881/Prices!F880) -> -0.081157876 | G886: =LN(Prices!G881/Prices!G880) -> -0.020778983 | H886: =LN(Prices!H881/Prices!H880) -> -0.080226464 | I886: =LN(Prices!I881/Prices!I880) -> -0.095366733 | J886: =LN(Prices!J881/Prices!J880) -> -0.079010413 | K886: =(Prices!K881-Prices!K880)/100 -> -0.00084999979 | L886: =LN(Prices!L881/Prices!L880) -> -0.095747492 | M886: =LN(Prices!M881/Prices!M880) -> -0.071487139 | N886: =LN(Prices!N881/Prices!N880) -> -0.091350284 | O886: =LN(Prices!O881/Prices!O880) -> -0.098375855
...

Sheet Histograms

Sheet Correlation Matrix
C1: B | D1: C | E1: D | F1: E | G1: F | H1: G | I1: H | J1: I | K1: J | L1: K | M1: L | N1: M | O1: N | P1: O | T1: row/column
C2: ACWX | D2: AGG | E2: EEM | F2: IEF | G2: RWR | H2: TIP | I2: VNQ | J2: VONV | K2: ^GSPC | L2: ^IRX | M2: ^MID | N2: ^RLG | O2: ^RLV | P2: ^RUT | S2: ACWX | T2: 1
A3: B | B3: ACWX | C3: =CORREL(_xlfn.VSTACK(INDIRECT("Returns!"&C$1&"7:"&C$1&"879"),INDIRECT("Returns!"&C$1&"1399:"&C$1&"2484")),_xlfn.VSTACK(INDIRECT("Returns!"&$A3&"7:"&$A3&"879"),INDIRECT("Returns!"&$A3&"1399:"&$A3&"2484"))) -> 1 | D3: =CORREL(_xlfn.VSTACK(INDIRECT("Returns!"&D$1&"7:"&D$1&"879"),INDIRECT("Returns!"&D$1&"1399:"&D$1&"2484")),_xlfn.VSTACK(INDIRECT("Returns!"&$A3&"7:"&$A3&"879"),INDIRECT("Returns!"&$A3&"1399:"&$A3&"2484"))) -> 0.22152024 | E3: =CORREL(_xlfn.VSTACK(INDIRECT("Returns!"&E$1&"7:"&E$1&"879"),INDIRECT("Returns!"&E$1&"1399:"&E$1&"2484")),_xlfn.VSTACK(INDIRECT("Returns!"&$A3&"7:"&$A3&"879"),INDIRECT("Returns!"&$A3&"1399:"&$A3&"2484"))) -> 0.90568604 | F3: =CORREL(_xlfn.VSTACK(INDIRECT("Returns!"&F$1&"7:"&F$1&"879"),INDIRECT("Returns!"&F$1&"1399:"&F$1&"2484")),_xlfn.VSTACK(INDIRECT("Returns!"&$A3&"7:"&$A3&"879"),INDIRECT("Returns!"&$A3&"1399:"&$A3&"2484"))) -> 0.078698733 | G3: =CORREL(_xlfn.VSTACK(INDIRECT("Returns!"&G$1&"7:"&G$1&"879"),INDIRECT("Returns!"&G$1&"1399:"&G$1&"2484")),_xlfn.VSTACK(INDIRECT("Returns!"&$A3&"7:"&$A3&"879"),INDIRECT("Returns!"&$A3&"1399:"&$A3&"2484"))) -> 0.51950329 | H3: =CORREL(_xlfn.VSTACK(INDIRECT("Returns!"&H$1&"7:"&H$1&"879"),INDIRECT("Returns!"&H$1&"1399:"&H$1&"2484")),_xlfn.VSTACK(INDIRECT("Returns!"&$A3&"7:"&$A3&"879"),INDIRECT("Returns!"&$A3&"1399:"&$A3&"2484"))) -> 0.18751279 | I3: =CORREL(_xlfn.VSTACK(INDIRECT("Returns!"&I$1&"7:"&I$1&"879"),INDIRECT("Returns!"&I$1&"1399:"&I$1&"2484")),_xlfn.VSTACK(INDIRECT("Returns!"&$A3&"7:"&$A3&"879"),INDIRECT("Returns!"&$A3&"1399:"&$A3&"2484"))) -> 0.53924106 | J3: =CORREL(_xlfn.VSTACK(INDIRECT("Returns!"&J$1&"7:"&J$1&"879"),INDIRECT("Returns!"&J$1&"1399:"&J$1&"2484")),_xlfn.VSTACK(INDIRECT("Returns!"&$A3&"7:"&$A3&"879"),INDIRECT("Returns!"&$A3&"1399:"&$A3&"2484"))) -> 0.79602623 | ... P3: =CORREL(_xlfn.VSTACK(INDIRECT("Returns!"&P$1&"7:"&P$1&"879"),INDIRECT("Returns!"&P$1&"1399:"&P$1&"2484")),_xlfn.VSTACK(INDIRECT("Returns!"&$A3&"7:"&$A3&"879"),INDIRECT("Returns!"&$A3&"1399:"&$A3&"2484"))) -> 0.75662886 | S3: AGG | T3: =T2+1 -> 2
A4: C | B4: AGG | C4: =CORREL(_xlfn.VSTACK(INDIRECT("Returns!"&C$1&"7:"&C$1&"879"),INDIRECT("Returns!"&C$1&"1399:"&C$1&"2484")),_xlfn.VSTACK(INDIRECT("Returns!"&$A4&"7:"&$A4&"879"),INDIRECT("Returns!"&$A4&"1399:"&$A4&"2484"))) -> 0.22152024 | D4: =CORREL(_xlfn.VSTACK(INDIRECT("Returns!"&D$1&"7:"&D$1&"879"),INDIRECT("Returns!"&D$1&"1399:"&D$1&"2484")),_xlfn.VSTACK(INDIRECT("Returns!"&$A4&"7:"&$A4&"879"),INDIRECT("Returns!"&$A4&"1399:"&$A4&"2484"))) -> 1 | E4: =CORREL(_xlfn.VSTACK(INDIRECT("Returns!"&E$1&"7:"&E$1&"879"),INDIRECT("Returns!"&E$1&"1399:"&E$1&"2484")),_xlfn.VSTACK(INDIRECT("Returns!"&$A4&"7:"&$A4&"879"),INDIRECT("Returns!"&$A4&"1399:"&$A4&"2484"))) -> 0.17019222 | F4: =CORREL(_xlfn.VSTACK(INDIRECT("Returns!"&F$1&"7:"&F$1&"879"),INDIRECT("Returns!"&F$1&"1399:"&F$1&"2484")),_xlfn.VSTACK(INDIRECT("Returns!"&$A4&"7:"&$A4&"879"),INDIRECT("Returns!"&$A4&"1399:"&$A4&"2484"))) -> 0.9652793 | G4: =CORREL(_xlfn.VSTACK(INDIRECT("Returns!"&G$1&"7:"&G$1&"879"),INDIRECT("Returns!"&G$1&"1399:"&G$1&"2484")),_xlfn.VSTACK(INDIRECT("Returns!"&$A4&"7:"&$A4&"879"),INDIRECT("Returns!"&$A4&"1399:"&$A4&"2484"))) -> 0.34046875 | H4: =CORREL(_xlfn.VSTACK(INDIRECT("Returns!"&H$1&"7:"&H$1&"879"),INDIRECT("Returns!"&H$1&"1399:"&H$1&"2484")),_xlfn.VSTACK(INDIRECT("Returns!"&$A4&"7:"&$A4&"879"),INDIRECT("Returns!"&$A4&"1399:"&$A4&"2484"))) -> 0.84575256 | I4: =CORREL(_xlfn.VSTACK(INDIRECT("Returns!"&I$1&"7:"&I$1&"879"),INDIRECT("Returns!"&I$1&"1399:"&I$1&"2484")),_xlfn.VSTACK(INDIRECT("Returns!"&$A4&"7:"&$A4&"879"),INDIRECT("Returns!"&$A4&"1399:"&$A4&"2484"))) -> 0.37177556 | J4: =CORREL(_xlfn.VSTACK(INDIRECT("Returns!"&J$1&"7:"&J$1&"879"),INDIRECT("Returns!"&J$1&"1399:"&J$1&"2484")),_xlfn.VSTACK(INDIRECT("Returns!"&$A4&"7:"&$A4&"879"),INDIRECT("Returns!"&$A4&"1399:"&$A4&"2484"))) -> 0.12604141 | ... P4: =CORREL(_xlfn.VSTACK(INDIRECT("Returns!"&P$1&"7:"&P$1&"879"),INDIRECT("Returns!"&P$1&"1399:"&P$1&"2484")),_xlfn.VSTACK(INDIRECT("Returns!"&$A4&"7:"&$A4&"879"),INDIRECT("Returns!"&$A4&"1399:"&$A4&"2484"))) -> 0.15348626 | S4: EEM | T4: =T3+1 -> 3
A5: D | B5: EEM | C5: =CORREL(_xlfn.VSTACK(INDIRECT("Returns!"&C$1&"7:"&C$1&"879"),INDIRECT("Returns!"&C$1&"1399:"&C$1&"2484")),_xlfn.VSTACK(INDIRECT("Returns!"&$A5&"7:"&$A5&"879"),INDIRECT("Returns!"&$A5&"1399:"&$A5&"2484"))) -> 0.90568604 | D5: =CORREL(_xlfn.VSTACK(INDIRECT("Returns!"&D$1&"7:"&D$1&"879"),INDIRECT("Returns!"&D$1&"1399:"&D$1&"2484")),_xlfn.VSTACK(INDIRECT("Returns!"&$A5&"7:"&$A5&"879"),INDIRECT("Returns!"&$A5&"1399:"&$A5&"2484"))) -> 0.17019222 | E5: =CORREL(_xlfn.VSTACK(INDIRECT("Returns!"&E$1&"7:"&E$1&"879"),INDIRECT("Returns!"&E$1&"1399:"&E$1&"2484")),_xlfn.VSTACK(INDIRECT("Returns!"&$A5&"7:"&$A5&"879"),INDIRECT("Returns!"&$A5&"1399:"&$A5&"2484"))) -> 1 | F5: =CORREL(_xlfn.VSTACK(INDIRECT("Returns!"&F$1&"7:"&F$1&"879"),INDIRECT("Returns!"&F$1&"1399:"&F$1&"2484")),_xlfn.VSTACK(INDIRECT("Returns!"&$A5&"7:"&$A5&"879"),INDIRECT("Returns!"&$A5&"1399:"&$A5&"2484"))) -> 0.042947545 | G5: =CORREL(_xlfn.VSTACK(INDIRECT("Returns!"&G$1&"7:"&G$1&"879"),INDIRECT("Returns!"&G$1&"1399:"&G$1&"2484")),_xlfn.VSTACK(INDIRECT("Returns!"&$A5&"7:"&$A5&"879"),INDIRECT("Returns!"&$A5&"1399:"&$A5&"2484"))) -> 0.38653614 | H5: =CORREL(_xlfn.VSTACK(INDIRECT("Returns!"&H$1&"7:"&H$1&"879"),INDIRECT("Returns!"&H$1&"1399:"&H$1&"2484")),_xlfn.VSTACK(INDIRECT("Returns!"&$A5&"7:"&$A5&"879"),INDIRECT("Returns!"&$A5&"1399:"&$A5&"2484"))) -> 0.13474346 | I5: =CORREL(_xlfn.VSTACK(INDIRECT("Returns!"&I$1&"7:"&I$1&"879"),INDIRECT("Returns!"&I$1&"1399:"&I$1&"2484")),_xlfn.VSTACK(INDIRECT("Returns!"&$A5&"7:"&$A5&"879"),INDIRECT("Returns!"&$A5&"1399:"&$A5&"2484"))) -> 0.40523451 | J5: =CORREL(_xlfn.VSTACK(INDIRECT("Returns!"&J$1&"7:"&J$1&"879"),INDIRECT("Returns!"&J$1&"1399:"&J$1&"2484")),_xlfn.VSTACK(INDIRECT("Returns!"&$A5&"7:"&$A5&"879"),INDIRECT("Returns!"&$A5&"1399:"&$A5&"2484"))) -> 0.64705571 | ... P5: =CORREL(_xlfn.VSTACK(INDIRECT("Returns!"&P$1&"7:"&P$1&"879"),INDIRECT("Returns!"&P$1&"1399:"&P$1&"2484")),_xlfn.VSTACK(INDIRECT("Returns!"&$A5&"7:"&$A5&"879"),INDIRECT("Returns!"&$A5&"1399:"&$A5&"2484"))) -> 0.64265609 | S5: IEF | T5: =T4+1 -> 4
A6: E | B6: IEF | C6: =CORREL(_xlfn.VSTACK(INDIRECT("Returns!"&C$1&"7:"&C$1&"879"),INDIRECT("Returns!"&C$1&"1399:"&C$1&"2484")),_xlfn.VSTACK(INDIRECT("Returns!"&$A6&"7:"&$A6&"879"),INDIRECT("Returns!"&$A6&"1399:"&$A6&"2484"))) -> 0.078698733 | D6: =CORREL(_xlfn.VSTACK(INDIRECT("Returns!"&D$1&"7:"&D$1&"879"),INDIRECT("Returns!"&D$1&"1399:"&D$1&"2484")),_xlfn.VSTACK(INDIRECT("Returns!"&$A6&"7:"&$A6&"879"),INDIRECT("Returns!"&$A6&"1399:"&$A6&"2484"))) -> 0.9652793 | E6: =CORREL(_xlfn.VSTACK(INDIRECT("Returns!"&E$1&"7:"&E$1&"879"),INDIRECT("Returns!"&E$1&"1399:"&E$1&"2484")),_xlfn.VSTACK(INDIRECT("Returns!"&$A6&"7:"&$A6&"879"),INDIRECT("Returns!"&$A6&"1399:"&$A6&"2484"))) -> 0.042947545 | F6: =CORREL(_xlfn.VSTACK(INDIRECT("Returns!"&F$1&"7:"&F$1&"879"),INDIRECT("Returns!"&F$1&"1399:"&F$1&"2484")),_xlfn.VSTACK(INDIRECT("Returns!"&$A6&"7:"&$A6&"879"),INDIRECT("Returns!"&$A6&"1399:"&$A6&"2484"))) -> 1 | G6: =CORREL(_xlfn.VSTACK(INDIRECT("Returns!"&G$1&"7:"&G$1&"879"),INDIRECT("Returns!"&G$1&"1399:"&G$1&"2484")),_xlfn.VSTACK(INDIRECT("Returns!"&$A6&"7:"&$A6&"879"),INDIRECT("Returns!"&$A6&"1399:"&$A6&"2484"))) -> 0.25096877 | H6: =CORREL(_xlfn.VSTACK(INDIRECT("Returns!"&H$1&"7:"&H$1&"879"),INDIRECT("Returns!"&H$1&"1399:"&H$1&"2484")),_xlfn.VSTACK(INDIRECT("Returns!"&$A6&"7:"&$A6&"879"),INDIRECT("Returns!"&$A6&"1399:"&$A6&"2484"))) -> 0.84402639 | I6: =CORREL(_xlfn.VSTACK(INDIRECT("Returns!"&I$1&"7:"&I$1&"879"),INDIRECT("Returns!"&I$1&"1399:"&I$1&"2484")),_xlfn.VSTACK(INDIRECT("Returns!"&$A6&"7:"&$A6&"879"),INDIRECT("Returns!"&$A6&"1399:"&$A6&"2484"))) -> 0.27975501 | J6: =CORREL(_xlfn.VSTACK(INDIRECT("Returns!"&J$1&"7:"&J$1&"879"),INDIRECT("Returns!"&J$1&"1399:"&J$1&"2484")),_xlfn.VSTACK(INDIRECT("Returns!"&$A6&"7:"&$A6&"879"),INDIRECT("Returns!"&$A6&"1399:"&$A6&"2484"))) -> -0.02401501 | ... P6: =CORREL(_xlfn.VSTACK(INDIRECT("Returns!"&P$1&"7:"&P$1&"879"),INDIRECT("Returns!"&P$1&"1399:"&P$1&"2484")),_xlfn.VSTACK(INDIRECT("Returns!"&$A6&"7:"&$A6&"879"),INDIRECT("Returns!"&$A6&"1399:"&$A6&"2484"))) -> 0.0087472368 | S6: RWR | T6: =T5+1 -> 5
A7: F | B7: RWR | C7: =CORREL(_xlfn.VSTACK(INDIRECT("Returns!"&C$1&"7:"&C$1&"879"),INDIRECT("Returns!"&C$1&"1399:"&C$1&"2484")),_xlfn.VSTACK(INDIRECT("Returns!"&$A7&"7:"&$A7&"879"),INDIRECT("Returns!"&$A7&"1399:"&$A7&"2484"))) -> 0.51950329 | D7: =CORREL(_xlfn.VSTACK(INDIRECT("Returns!"&D$1&"7:"&D$1&"879"),INDIRECT("Returns!"&D$1&"1399:"&D$1&"2484")),_xlfn.VSTACK(INDIRECT("Returns!"&$A7&"7:"&$A7&"879"),INDIRECT("Returns!"&$A7&"1399:"&$A7&"2484"))) -> 0.34046875 | E7: =CORREL(_xlfn.VSTACK(INDIRECT("Returns!"&E$1&"7:"&E$1&"879"),INDIRECT("Returns!"&E$1&"1399:"&E$1&"2484")),_xlfn.VSTACK(INDIRECT("Returns!"&$A7&"7:"&$A7&"879"),INDIRECT("Returns!"&$A7&"1399:"&$A7&"2484"))) -> 0.38653614 | F7: =CORREL(_xlfn.VSTACK(INDIRECT("Returns!"&F$1&"7:"&F$1&"879"),INDIRECT("Returns!"&F$1&"1399:"&F$1&"2484")),_xlfn.VSTACK(INDIRECT("Returns!"&$A7&"7:"&$A7&"879"),INDIRECT("Returns!"&$A7&"1399:"&$A7&"2484"))) -> 0.25096877 | G7: =CORREL(_xlfn.VSTACK(INDIRECT("Returns!"&G$1&"7:"&G$1&"879"),INDIRECT("Returns!"&G$1&"1399:"&G$1&"2484")),_xlfn.VSTACK(INDIRECT("Returns!"&$A7&"7:"&$A7&"879"),INDIRECT("Returns!"&$A7&"1399:"&$A7&"2484"))) -> 1 | H7: =CORREL(_xlfn.VSTACK(INDIRECT("Returns!"&H$1&"7:"&H$1&"879"),INDIRECT("Returns!"&H$1&"1399:"&H$1&"2484")),_xlfn.VSTACK(INDIRECT("Returns!"&$A7&"7:"&$A7&"879"),INDIRECT("Returns!"&$A7&"1399:"&$A7&"2484"))) -> 0.31057339 | I7: =CORREL(_xlfn.VSTACK(INDIRECT("Returns!"&I$1&"7:"&I$1&"879"),INDIRECT("Returns!"&I$1&"1399:"&I$1&"2484")),_xlfn.VSTACK(INDIRECT("Returns!"&$A7&"7:"&$A7&"879"),INDIRECT("Returns!"&$A7&"1399:"&$A7&"2484"))) -> 0.98572895 | J7: =CORREL(_xlfn.VSTACK(INDIRECT("Returns!"&J$1&"7:"&J$1&"879"),INDIRECT("Returns!"&J$1&"1399:"&J$1&"2484")),_xlfn.VSTACK(INDIRECT("Returns!"&$A7&"7:"&$A7&"879"),INDIRECT("Returns!"&$A7&"1399:"&$A7&"2484"))) -> 0.68461119 | ... P7: =CORREL(_xlfn.VSTACK(INDIRECT("Returns!"&P$1&"7:"&P$1&"879"),INDIRECT("Returns!"&P$1&"1399:"&P$1&"2484")),_xlfn.VSTACK(INDIRECT("Returns!"&$A7&"7:"&$A7&"879"),INDIRECT("Returns!"&$A7&"1399:"&$A7&"2484"))) -> 0.62327184 | S7: TIP | T7: =T6+1 -> 6
A8: G | B8: TIP | C8: =CORREL(_xlfn.VSTACK(INDIRECT("Returns!"&C$1&"7:"&C$1&"879"),INDIRECT("Returns!"&C$1&"1399:"&C$1&"2484")),_xlfn.VSTACK(INDIRECT("Returns!"&$A8&"7:"&$A8&"879"),INDIRECT("Returns!"&$A8&"1399:"&$A8&"2484"))) -> 0.18751279 | D8: =CORREL(_xlfn.VSTACK(INDIRECT("Returns!"&D$1&"7:"&D$1&"879"),INDIRECT("Returns!"&D$1&"1399:"&D$1&"2484")),_xlfn.VSTACK(INDIRECT("Returns!"&$A8&"7:"&$A8&"879"),INDIRECT("Returns!"&$A8&"1399:"&$A8&"2484"))) -> 0.84575256 | E8: =CORREL(_xlfn.VSTACK(INDIRECT("Returns!"&E$1&"7:"&E$1&"879"),INDIRECT("Returns!"&E$1&"1399:"&E$1&"2484")),_xlfn.VSTACK(INDIRECT("Returns!"&$A8&"7:"&$A8&"879"),INDIRECT("Returns!"&$A8&"1399:"&$A8&"2484"))) -> 0.13474346 | F8: =CORREL(_xlfn.VSTACK(INDIRECT("Returns!"&F$1&"7:"&F$1&"879"),INDIRECT("Returns!"&F$1&"1399:"&F$1&"2484")),_xlfn.VSTACK(INDIRECT("Returns!"&$A8&"7:"&$A8&"879"),INDIRECT("Returns!"&$A8&"1399:"&$A8&"2484"))) -> 0.84402639 | G8: =CORREL(_xlfn.VSTACK(INDIRECT("Returns!"&G$1&"7:"&G$1&"879"),INDIRECT("Returns!"&G$1&"1399:"&G$1&"2484")),_xlfn.VSTACK(INDIRECT("Returns!"&$A8&"7:"&$A8&"879"),INDIRECT("Returns!"&$A8&"1399:"&$A8&"2484"))) -> 0.31057339 | H8: =CORREL(_xlfn.VSTACK(INDIRECT("Returns!"&H$1&"7:"&H$1&"879"),INDIRECT("Returns!"&H$1&"1399:"&H$1&"2484")),_xlfn.VSTACK(INDIRECT("Returns!"&$A8&"7:"&$A8&"879"),INDIRECT("Returns!"&$A8&"1399:"&$A8&"2484"))) -> 1 | I8: =CORREL(_xlfn.VSTACK(INDIRECT("Returns!"&I$1&"7:"&I$1&"879"),INDIRECT("Returns!"&I$1&"1399:"&I$1&"2484")),_xlfn.VSTACK(INDIRECT("Returns!"&$A8&"7:"&$A8&"879"),INDIRECT("Returns!"&$A8&"1399:"&$A8&"2484"))) -> 0.33608118 | J8: =CORREL(_xlfn.VSTACK(INDIRECT("Returns!"&J$1&"7:"&J$1&"879"),INDIRECT("Returns!"&J$1&"1399:"&J$1&"2484")),_xlfn.VSTACK(INDIRECT("Returns!"&$A8&"7:"&$A8&"879"),INDIRECT("Returns!"&$A8&"1399:"&$A8&"2484"))) -> 0.12324602 | ... P8: =CORREL(_xlfn.VSTACK(INDIRECT("Returns!"&P$1&"7:"&P$1&"879"),INDIRECT("Returns!"&P$1&"1399:"&P$1&"2484")),_xlfn.VSTACK(INDIRECT("Returns!"&$A8&"7:"&$A8&"879"),INDIRECT("Returns!"&$A8&"1399:"&$A8&"2484"))) -> 0.12512782 | S8: VNQ | T8: =T7+1 -> 7
A9: H | B9: VNQ | C9: =CORREL(_xlfn.VSTACK(INDIRECT("Returns!"&C$1&"7:"&C$1&"879"),INDIRECT("Returns!"&C$1&"1399:"&C$1&"2484")),_xlfn.VSTACK(INDIRECT("Returns!"&$A9&"7:"&$A9&"879"),INDIRECT("Returns!"&$A9&"1399:"&$A9&"2484"))) -> 0.53924106 | D9: =CORREL(_xlfn.VSTACK(INDIRECT("Returns!"&D$1&"7:"&D$1&"879"),INDIRECT("Returns!"&D$1&"1399:"&D$1&"2484")),_xlfn.VSTACK(INDIRECT("Returns!"&$A9&"7:"&$A9&"879"),INDIRECT("Returns!"&$A9&"1399:"&$A9&"2484"))) -> 0.37177556 | E9: =CORREL(_xlfn.VSTACK(INDIRECT("Returns!"&E$1&"7:"&E$1&"879"),INDIRECT("Returns!"&E$1&"1399:"&E$1&"2484")),_xlfn.VSTACK(INDIRECT("Returns!"&$A9&"7:"&$A9&"879"),INDIRECT("Returns!"&$A9&"1399:"&$A9&"2484"))) -> 0.40523451 | F9: =CORREL(_xlfn.VSTACK(INDIRECT("Returns!"&F$1&"7:"&F$1&"879"),INDIRECT("Returns!"&F$1&"1399:"&F$1&"2484")),_xlfn.VSTACK(INDIRECT("Returns!"&$A9&"7:"&$A9&"879"),INDIRECT("Returns!"&$A9&"1399:"&$A9&"2484"))) -> 0.27975501 | G9: =CORREL(_xlfn.VSTACK(INDIRECT("Returns!"&G$1&"7:"&G$1&"879"),INDIRECT("Returns!"&G$1&"1399:"&G$1&"2484")),_xlfn.VSTACK(INDIRECT("Returns!"&$A9&"7:"&$A9&"879"),INDIRECT("Returns!"&$A9&"1399:"&$A9&"2484"))) -> 0.98572895 | H9: =CORREL(_xlfn.VSTACK(INDIRECT("Returns!"&H$1&"7:"&H$1&"879"),INDIRECT("Returns!"&H$1&"1399:"&H$1&"2484")),_xlfn.VSTACK(INDIRECT("Returns!"&$A9&"7:"&$A9&"879"),INDIRECT("Returns!"&$A9&"1399:"&$A9&"2484"))) -> 0.33608118 | I9: =CORREL(_xlfn.VSTACK(INDIRECT("Returns!"&I$1&"7:"&I$1&"879"),INDIRECT("Returns!"&I$1&"1399:"&I$1&"2484")),_xlfn.VSTACK(INDIRECT("Returns!"&$A9&"7:"&$A9&"879"),INDIRECT("Returns!"&$A9&"1399:"&$A9&"2484"))) -> 1 | J9: =CORREL(_xlfn.VSTACK(INDIRECT("Returns!"&J$1&"7:"&J$1&"879"),INDIRECT("Returns!"&J$1&"1399:"&J$1&"2484")),_xlfn.VSTACK(INDIRECT("Returns!"&$A9&"7:"&$A9&"879"),INDIRECT("Returns!"&$A9&"1399:"&$A9&"2484"))) -> 0.69406223 | ... P9: =CORREL(_xlfn.VSTACK(INDIRECT("Returns!"&P$1&"7:"&P$1&"879"),INDIRECT("Returns!"&P$1&"1399:"&P$1&"2484")),_xlfn.VSTACK(INDIRECT("Returns!"&$A9&"7:"&$A9&"879"),INDIRECT("Returns!"&$A9&"1399:"&$A9&"2484"))) -> 0.63683824 | S9: VONV | T9: =T8+1 -> 8
A10: I | B10: VONV | C10: =CORREL(_xlfn.VSTACK(INDIRECT("Returns!"&C$1&"7:"&C$1&"879"),INDIRECT("Returns!"&C$1&"1399:"&C$1&"2484")),_xlfn.VSTACK(INDIRECT("Returns!"&$A10&"7:"&$A10&"879"),INDIRECT("Returns!"&$A10&"1399:"&$A10&"2484"))) -> 0.79602623 | D10: =CORREL(_xlfn.VSTACK(INDIRECT("Returns!"&D$1&"7:"&D$1&"879"),INDIRECT("Returns!"&D$1&"1399:"&D$1&"2484")),_xlfn.VSTACK(INDIRECT("Returns!"&$A10&"7:"&$A10&"879"),INDIRECT("Returns!"&$A10&"1399:"&$A10&"2484"))) -> 0.12604141 | E10: =CORREL(_xlfn.VSTACK(INDIRECT("Returns!"&E$1&"7:"&E$1&"879"),INDIRECT("Returns!"&E$1&"1399:"&E$1&"2484")),_xlfn.VSTACK(INDIRECT("Returns!"&$A10&"7:"&$A10&"879"),INDIRECT("Returns!"&$A10&"1399:"&$A10&"2484"))) -> 0.64705571 | F10: =CORREL(_xlfn.VSTACK(INDIRECT("Returns!"&F$1&"7:"&F$1&"879"),INDIRECT("Returns!"&F$1&"1399:"&F$1&"2484")),_xlfn.VSTACK(INDIRECT("Returns!"&$A10&"7:"&$A10&"879"),INDIRECT("Returns!"&$A10&"1399:"&$A10&"2484"))) -> -0.02401501 | G10: =CORREL(_xlfn.VSTACK(INDIRECT("Returns!"&G$1&"7:"&G$1&"879"),INDIRECT("Returns!"&G$1&"1399:"&G$1&"2484")),_xlfn.VSTACK(INDIRECT("Returns!"&$A10&"7:"&$A10&"879"),INDIRECT("Returns!"&$A10&"1399:"&$A10&"2484"))) -> 0.68461119 | H10: =CORREL(_xlfn.VSTACK(INDIRECT("Returns!"&H$1&"7:"&H$1&"879"),INDIRECT("Returns!"&H$1&"1399:"&H$1&"2484")),_xlfn.VSTACK(INDIRECT("Returns!"&$A10&"7:"&$A10&"879"),INDIRECT("Returns!"&$A10&"1399:"&$A10&"2484"))) -> 0.12324602 | I10: =CORREL(_xlfn.VSTACK(INDIRECT("Returns!"&I$1&"7:"&I$1&"879"),INDIRECT("Returns!"&I$1&"1399:"&I$1&"2484")),_xlfn.VSTACK(INDIRECT("Returns!"&$A10&"7:"&$A10&"879"),INDIRECT("Returns!"&$A10&"1399:"&$A10&"2484"))) -> 0.69406223 | J10: =CORREL(_xlfn.VSTACK(INDIRECT("Returns!"&J$1&"7:"&J$1&"879"),INDIRECT("Returns!"&J$1&"1399:"&J$1&"2484")),_xlfn.VSTACK(INDIRECT("Returns!"&$A10&"7:"&$A10&"879"),INDIRECT("Returns!"&$A10&"1399:"&$A10&"2484"))) -> 1 | ... P10: =CORREL(_xlfn.VSTACK(INDIRECT("Returns!"&P$1&"7:"&P$1&"879"),INDIRECT("Returns!"&P$1&"1399:"&P$1&"2484")),_xlfn.VSTACK(INDIRECT("Returns!"&$A10&"7:"&$A10&"879"),INDIRECT("Returns!"&$A10&"1399:"&$A10&"2484"))) -> 0.88061643 | S10: ^GSPC | T10: =T9+1 -> 9
A11: J | B11: ^GSPC | C11: =CORREL(_xlfn.VSTACK(INDIRECT("Returns!"&C$1&"7:"&C$1&"879"),INDIRECT("Returns!"&C$1&"1399:"&C$1&"2484")),_xlfn.VSTACK(INDIRECT("Returns!"&$A11&"7:"&$A11&"879"),INDIRECT("Returns!"&$A11&"1399:"&$A11&"2484"))) -> 0.81882142 | D11: =CORREL(_xlfn.VSTACK(INDIRECT("Returns!"&D$1&"7:"&D$1&"879"),INDIRECT("Returns!"&D$1&"1399:"&D$1&"2484")),_xlfn.VSTACK(INDIRECT("Returns!"&$A11&"7:"&$A11&"879"),INDIRECT("Returns!"&$A11&"1399:"&$A11&"2484"))) -> 0.13700426 | E11: =CORREL(_xlfn.VSTACK(INDIRECT("Returns!"&E$1&"7:"&E$1&"879"),INDIRECT("Returns!"&E$1&"1399:"&E$1&"2484")),_xlfn.VSTACK(INDIRECT("Returns!"&$A11&"7:"&$A11&"879"),INDIRECT("Returns!"&$A11&"1399:"&$A11&"2484"))) -> 0.70064437 | F11: =CORREL(_xlfn.VSTACK(INDIRECT("Returns!"&F$1&"7:"&F$1&"879"),INDIRECT("Returns!"&F$1&"1399:"&F$1&"2484")),_xlfn.VSTACK(INDIRECT("Returns!"&$A11&"7:"&$A11&"879"),INDIRECT("Returns!"&$A11&"1399:"&$A11&"2484"))) -> -0.016900284 | G11: =CORREL(_xlfn.VSTACK(INDIRECT("Returns!"&G$1&"7:"&G$1&"879"),INDIRECT("Returns!"&G$1&"1399:"&G$1&"2484")),_xlfn.VSTACK(INDIRECT("Returns!"&$A11&"7:"&$A11&"879"),INDIRECT("Returns!"&$A11&"1399:"&$A11&"2484"))) -> 0.59679677 | H11: =CORREL(_xlfn.VSTACK(INDIRECT("Returns!"&H$1&"7:"&H$1&"879"),INDIRECT("Returns!"&H$1&"1399:"&H$1&"2484")),_xlfn.VSTACK(INDIRECT("Returns!"&$A11&"7:"&$A11&"879"),INDIRECT("Returns!"&$A11&"1399:"&$A11&"2484"))) -> 0.12041591 | I11: =CORREL(_xlfn.VSTACK(INDIRECT("Returns!"&I$1&"7:"&I$1&"879"),INDIRECT("Returns!"&I$1&"1399:"&I$1&"2484")),_xlfn.VSTACK(INDIRECT("Returns!"&$A11&"7:"&$A11&"879"),INDIRECT("Returns!"&$A11&"1399:"&$A11&"2484"))) -> 0.60966834 | J11: =CORREL(_xlfn.VSTACK(INDIRECT("Returns!"&J$1&"7:"&J$1&"879"),INDIRECT("Returns!"&J$1&"1399:"&J$1&"2484")),_xlfn.VSTACK(INDIRECT("Returns!"&$A11&"7:"&$A11&"879"),INDIRECT("Returns!"&$A11&"1399:"&$A11&"2484"))) -> 0.91619799 | ... P11: =CORREL(_xlfn.VSTACK(INDIRECT("Returns!"&P$1&"7:"&P$1&"879"),INDIRECT("Returns!"&P$1&"1399:"&P$1&"2484")),_xlfn.VSTACK(INDIRECT("Returns!"&$A11&"7:"&$A11&"879"),INDIRECT("Returns!"&$A11&"1399:"&$A11&"2484"))) -> 0.85555459 | S11: ^IRX | T11: =T10+1 -> 10
A12: K | B12: ^IRX | C12: =CORREL(_xlfn.VSTACK(INDIRECT("Returns!"&C$1&"7:"&C$1&"879"),INDIRECT("Returns!"&C$1&"1399:"&C$1&"2484")),_xlfn.VSTACK(INDIRECT("Returns!"&$A12&"7:"&$A12&"879"),INDIRECT("Returns!"&$A12&"1399:"&$A12&"2484"))) -> 0.0067133244 | D12: =CORREL(_xlfn.VSTACK(INDIRECT("Returns!"&D$1&"7:"&D$1&"879"),INDIRECT("Returns!"&D$1&"1399:"&D$1&"2484")),_xlfn.VSTACK(INDIRECT("Returns!"&$A12&"7:"&$A12&"879"),INDIRECT("Returns!"&$A12&"1399:"&$A12&"2484"))) -> -0.19972578 | E12: =CORREL(_xlfn.VSTACK(INDIRECT("Returns!"&E$1&"7:"&E$1&"879"),INDIRECT("Returns!"&E$1&"1399:"&E$1&"2484")),_xlfn.VSTACK(INDIRECT("Returns!"&$A12&"7:"&$A12&"879"),INDIRECT("Returns!"&$A12&"1399:"&$A12&"2484"))) -> 0.016294376 | F12: =CORREL(_xlfn.VSTACK(INDIRECT("Returns!"&F$1&"7:"&F$1&"879"),INDIRECT("Returns!"&F$1&"1399:"&F$1&"2484")),_xlfn.VSTACK(INDIRECT("Returns!"&$A12&"7:"&$A12&"879"),INDIRECT("Returns!"&$A12&"1399:"&$A12&"2484"))) -> -0.21285992 | G12: =CORREL(_xlfn.VSTACK(INDIRECT("Returns!"&G$1&"7:"&G$1&"879"),INDIRECT("Returns!"&G$1&"1399:"&G$1&"2484")),_xlfn.VSTACK(INDIRECT("Returns!"&$A12&"7:"&$A12&"879"),INDIRECT("Returns!"&$A12&"1399:"&$A12&"2484"))) -> -0.018492949 | H12: =CORREL(_xlfn.VSTACK(INDIRECT("Returns!"&H$1&"7:"&H$1&"879"),INDIRECT("Returns!"&H$1&"1399:"&H$1&"2484")),_xlfn.VSTACK(INDIRECT("Returns!"&$A12&"7:"&$A12&"879"),INDIRECT("Returns!"&$A12&"1399:"&$A12&"2484"))) -> -0.19969563 | I12: =CORREL(_xlfn.VSTACK(INDIRECT("Returns!"&I$1&"7:"&I$1&"879"),INDIRECT("Returns!"&I$1&"1399:"&I$1&"2484")),_xlfn.VSTACK(INDIRECT("Returns!"&$A12&"7:"&$A12&"879"),INDIRECT("Returns!"&$A12&"1399:"&$A12&"2484"))) -> -0.025467888 | J12: =CORREL(_xlfn.VSTACK(INDIRECT("Returns!"&J$1&"7:"&J$1&"879"),INDIRECT("Returns!"&J$1&"1399:"&J$1&"2484")),_xlfn.VSTACK(INDIRECT("Returns!"&$A12&"7:"&$A12&"879"),INDIRECT("Returns!"&$A12&"1399:"&$A12&"2484"))) -> 0.033366296 | ... P12: =CORREL(_xlfn.VSTACK(INDIRECT("Returns!"&P$1&"7:"&P$1&"879"),INDIRECT("Returns!"&P$1&"1399:"&P$1&"2484")),_xlfn.VSTACK(INDIRECT("Returns!"&$A12&"7:"&$A12&"879"),INDIRECT("Returns!"&$A12&"1399:"&$A12&"2484"))) -> 0.022566479 | S12: ^MID | T12: =T11+1 -> 11
A13: L | B13: ^MID | C13: =CORREL(_xlfn.VSTACK(INDIRECT("Returns!"&C$1&"7:"&C$1&"879"),INDIRECT("Returns!"&C$1&"1399:"&C$1&"2484")),_xlfn.VSTACK(INDIRECT("Returns!"&$A13&"7:"&$A13&"879"),INDIRECT("Returns!"&$A13&"1399:"&$A13&"2484"))) -> 0.78274624 | D13: =CORREL(_xlfn.VSTACK(INDIRECT("Returns!"&D$1&"7:"&D$1&"879"),INDIRECT("Returns!"&D$1&"1399:"&D$1&"2484")),_xlfn.VSTACK(INDIRECT("Returns!"&$A13&"7:"&$A13&"879"),INDIRECT("Returns!"&$A13&"1399:"&$A13&"2484"))) -> 0.14851952 | E13: =CORREL(_xlfn.VSTACK(INDIRECT("Returns!"&E$1&"7:"&E$1&"879"),INDIRECT("Returns!"&E$1&"1399:"&E$1&"2484")),_xlfn.VSTACK(INDIRECT("Returns!"&$A13&"7:"&$A13&"879"),INDIRECT("Returns!"&$A13&"1399:"&$A13&"2484"))) -> 0.65623861 | F13: =CORREL(_xlfn.VSTACK(INDIRECT("Returns!"&F$1&"7:"&F$1&"879"),INDIRECT("Returns!"&F$1&"1399:"&F$1&"2484")),_xlfn.VSTACK(INDIRECT("Returns!"&$A13&"7:"&$A13&"879"),INDIRECT("Returns!"&$A13&"1399:"&$A13&"2484"))) -> 0.00021783018 | G13: =CORREL(_xlfn.VSTACK(INDIRECT("Returns!"&G$1&"7:"&G$1&"879"),INDIRECT("Returns!"&G$1&"1399:"&G$1&"2484")),_xlfn.VSTACK(INDIRECT("Returns!"&$A13&"7:"&$A13&"879"),INDIRECT("Returns!"&$A13&"1399:"&$A13&"2484"))) -> 0.66914421 | H13: =CORREL(_xlfn.VSTACK(INDIRECT("Returns!"&H$1&"7:"&H$1&"879"),INDIRECT("Returns!"&H$1&"1399:"&H$1&"2484")),_xlfn.VSTACK(INDIRECT("Returns!"&$A13&"7:"&$A13&"879"),INDIRECT("Returns!"&$A13&"1399:"&$A13&"2484"))) -> 0.12835482 | I13: =CORREL(_xlfn.VSTACK(INDIRECT("Returns!"&I$1&"7:"&I$1&"879"),INDIRECT("Returns!"&I$1&"1399:"&I$1&"2484")),_xlfn.VSTACK(INDIRECT("Returns!"&$A13&"7:"&$A13&"879"),INDIRECT("Returns!"&$A13&"1399:"&$A13&"2484"))) -> 0.67939285 | J13: =CORREL(_xlfn.VSTACK(INDIRECT("Returns!"&J$1&"7:"&J$1&"879"),INDIRECT("Returns!"&J$1&"1399:"&J$1&"2484")),_xlfn.VSTACK(INDIRECT("Returns!"&$A13&"7:"&$A13&"879"),INDIRECT("Returns!"&$A13&"1399:"&$A13&"2484"))) -> 0.92843061 | ... P13: =CORREL(_xlfn.VSTACK(INDIRECT("Returns!"&P$1&"7:"&P$1&"879"),INDIRECT("Returns!"&P$1&"1399:"&P$1&"2484")),_xlfn.VSTACK(INDIRECT("Returns!"&$A13&"7:"&$A13&"879"),INDIRECT("Returns!"&$A13&"1399:"&$A13&"2484"))) -> 0.96403514 | S13: ^RLG | T13: =T12+1 -> 12
